Workbook

Sheet RAW_DATA
A1: Employee_ID | B1: First_Name | C1: Last_Name | D1: Age | E1: Department_Region | F1: Status | G1: Join_Date | H1: Salary | I1: Email | J1: Phone | K1: Performance_Score | L1: Remote_Work
A2: EMP1000 | B2: Bob | C2: Davis | D2: 25 | E2: DevOps-California | F2: Active | G2: 44288 | H2: 59767.65 | I2: bob.davis@example.com | J2: -1651623197 | K2: Average | L2: TRUE
A3: EMP1001 | B3: Bob | C3: Brown | E3: Finance-Texas | F3: Active | G3: 44022 | H3: 65304.66 | I3: bob.brown@example.com | J3: -1898471390 | K3: Excellent | L3: TRUE
A4: EMP1002 | B4: Alice | C4: Jones | E4: Admin-Nevada | F4: Pending | G4: 45267 | H4: 88145.9 | I4: alice.jones@example.com | J4: -5596363211 | K4: Good | L4: TRUE
A5: EMP1003 | B5: Eva | C5: Davis | D5: 25 | E5: Admin-Nevada | F5: Inactive | G5: 44527 | H5: 69450.99 | I5: eva.davis@example.com | J5: -3476490784 | K5: Good | L5: TRUE
A6: EMP1004 | B6: Frank | C6: Williams | D6: 25 | E6: Cloud Tech-Florida | F6: Active | G6: 44566 | H6: 109324.61 | I6: frank.williams@example.com | J6: -1586734256 | K6: Poor | L6: FALSE
A7: EMP1005 | B7: Alice | C7: Garcia | D7: 40 | E7: Sales-Texas | F7: Inactive | G7: 43992 | H7: 88642.84 | I7: alice.garcia@example.com | J7: -5409003485 | K7: Good | L7: FALSE
A8: EMP1006 | B8: Frank | C8: Jones | E8: Admin-Nevada | F8: Active | G8: 43924 | H8: 96288.43 | I8: frank.jones@example.com | J8: -4518376063 | K8: Good | L8: FALSE
A9: EMP1007 | B9: Bob | C9: Jones | D9: 30 | E9: Cloud Tech-Florida | F9: Inactive | G9: 44759 | H9: 94497.91 | I9: bob.jones@example.com | J9: -4134327559 | K9: Average | L9: TRUE
A10: EMP1008 | B10: Frank | C10: Davis | D10: 35 | E10: Admin-Nevada | F10: Inactive | G10: 45268 | H10: 115565.82 | I10: frank.davis@example.com | J10: -4177656123 | K10: Excellent | L10: TRUE
A11: EMP1009 | B11: Charlie | C11: Johnson | E11: DevOps-New York | F11: Active | G11: 44777 | H11: 76561.88 | I11: charlie.johnson@example.com | J11: -8156985699 | K11: Excellent | L11: TRUE
A12: EMP1010 | B12: David | C12: Williams | D12: 35 | E12: Cloud Tech-New York | F12: Active | G12: 45479 | H12: 72081.71 | I12: david.williams@example.com | J12: -2720634590 | K12: Average | L12: FALSE
A13: EMP1011 | B13: David | C13: Davis | E13: DevOps-California | F13: Active | G13: 45173 | H13: 84946.19 | I13: david.davis@example.com | J13: -1238296576 | K13: Poor | L13: TRUE
A14: EMP1012 | B14: Heidi | C14: Williams | D14: 30 | E14: HR-New York | F14: Active | G14: 45356 | H14: 89295.77 | I14: heidi.williams@example.com | J14: -2429543164 | K14: Excellent | L14: FALSE
A15: EMP1013 | B15: Grace | C15: Williams | E15: Finance-California | F15: Active | G15: 44114 | H15: 85666.84 | I15: grace.williams@example.com | J15: -2669300892 | K15: Good | L15: FALSE
A16: EMP1014 | B16: Alice | C16: Garcia | D16: 25 | E16: Admin-Nevada | F16: Active | G16: 45453 | H16: 97633.68 | I16: alice.garcia@example.com | J16: -1734206968 | K16: Excellent | L16: TRUE
A17: EMP1015 | B17: Grace | C17: Jones | D17: 40 | E17: Sales-Florida | F17: Pending | G17: 44345 | H17: 117975.49 | I17: grace.jones@example.com | J17: -4215291085 | K17: Good | L17: TRUE
A18: EMP1016 | B18: Alice | C18: Brown | D18: 25 | E18: DevOps-Illinois | F18: Inactive | G18: 45405 | H18: 94867.33 | I18: alice.brown@example.com | J18: -7713334475 | K18: Poor | L18: FALSE
A19: EMP1017 | B19: Grace | C19: Garcia | D19: 30 | E19: Finance-Texas | F19: Pending | G19: 45624 | H19: 100377.65 | I19: grace.garcia@example.com | J19: -2639343625 | K19: Average | L19: TRUE
A20: EMP1018 | B20: Charlie | C20: Garcia | E20: Cloud Tech-Nevada | F20: Inactive | G20: 45554 | H20: 94726.46 | I20: charlie.garcia@example.com | J20: -2044397358 | K20: Excellent | L20: FALSE
A21: EMP1019 | B21: Charlie | C21: Williams | D21: 35 | E21: Admin-Illinois | F21: Pending | G21: 43832 | H21: 91926.12 | I21: charlie.williams@example.com | J21: -7107256365 | K21: Average | L21: TRUE
A22: EMP1020 | B22: Bob | C22: Miller | D22: 35 | E22: HR-New York | F22: Active | G22: 44324 | H22: 111460.67 | I22: bob.miller@example.com | J22: -9411800536 | K22: Excellent | L22: TRUE
A23: EMP1021 | B23: Bob | C23: Jones | D23: 40 | E23: Cloud Tech-Illinois | F23: Active | G23: 44093 | H23: 96182.56 | I23: bob.jones@example.com | J23: -5990048963 | K23: Good | L23: FALSE
A24: EMP1022 | B24: Charlie | C24: Johnson | D24: 35 | E24: Sales-Illinois | F24: Inactive | G24: 44264 | H24: 115023.94 | I24: charlie.johnson@example.com | J24: -6528092427 | K24: Average | L24: TRUE
A25: EMP1023 | B25: David | C25: Garcia | D25: 35 | E25: Finance-Nevada | F25: Pending | G25: 44595 | H25: 80667.01 | I25: david.garcia@example.com | J25: -7572158623 | K25: Excellent | L25: FALSE
A26: EMP1024 | B26: Bob | C26: Brown | D26: 30 | E26: Admin-Texas | F26: Inactive | G26: 43874 | H26: 91181.61 | I26: bob.brown@example.com | J26: -1502745643 | K26: Good | L26: TRUE
A27: EMP1025 | B27: David | C27: Miller | D27: 25 | E27: Cloud Tech-Nevada | F27: Pending | G27: 43951 | H27: 66025.92 | I27: david.miller@example.com | J27: -9485625727 | K27: Average | L27: FALSE
A28: EMP1026 | B28: Frank | C28: Miller | D28: 25 | E28: Sales-New York | F28: Inactive | G28: 45201 | H28: 83979.01 | I28: frank.miller@example.com | J28: -7032032073 | K28: Average | L28: FALSE
A29: EMP1027 | B29: Heidi | C29: Johnson | D29: 30 | E29: Finance-Florida | F29: Active | G29: 44024 | H29: 56785.16 | I29: heidi.johnson@example.com | J29: -2761707586 | K29: Excellent | L29: TRUE
A30: EMP1028 | B30: Grace | C30: Garcia | D30: 40 | E30: Finance-Nevada | F30: Active | G30: 45210 | H30: 95741.88 | I30: grace.garcia@example.com | J30: -7712151341 | K30: Excellent | L30: FALSE
A31: EMP1029 | B31: Alice | C31: Brown | D31: 40 | E31: DevOps-California | F31: Active | G31: 44340 | H31: 63411.31 | I31: alice.brown@example.com | J31: -2849939088 | K31: Excellent | L31: TRUE
A32: EMP1030 | B32: Charlie | C32: Jones | D32: 40 | E32: Admin-California | F32: Inactive | G32: 44342 | H32: 111214.02 | I32: charlie.jones@example.com | J32: -2613715040 | K32: Good | L32: TRUE
... A37: EMP1035 | B37: Frank | C37: Jones | D37: 25 | E37: Cloud Tech-Illinois | F37: Inactive | G37: 44860 | H37: 114357.1 | I37: frank.jones@example.com | J37: -6642147648 | K37: Excellent | L37: TRUE
A38: EMP1036 | B38: Alice | C38: Brown | E38: Cloud Tech-New York | F38: Active | G38: 45049 | H38: 54757.26 | I38: alice.brown@example.com | J38: -2515837766 | K38: Poor | L38: FALSE
A39: EMP1037 | B39: Grace | C39: Smith | D39: 25 | E39: Sales-New York | F39: Pending | G39: 45048 | H39: 52781.92 | I39: grace.smith@example.com | J39: -4996165925 | K39: Average | L39: TRUE
A40: EMP1038 | B40: Frank | C40: Smith | D40: 35 | E40: Admin-Nevada | F40: Pending | G40: 44474 | H40: 66708.02 | I40: frank.smith@example.com | J40: -6108573277 | K40: Good | L40: TRUE
A41: EMP1039 | B41: Eva | C41: Williams | D41: 40 | E41: HR-Texas | F41: Active | G41: 44769 | H41: 93481.15 | I41: eva.williams@example.com | J41: -8147617421 | K41: Poor | L41: FALSE
A42: EMP1040 | B42: Bob | C42: Williams | D42: 25 | E42: Sales-New York | F42: Pending | G42: 44374 | H42: 59271.96 | I42: bob.williams@example.com | J42: -4386490809 | K42: Excellent | L42: TRUE
A43: EMP1041 | B43: Bob | C43: Davis | D43: 30 | E43: HR-California | F43: Active | G43: 44728 | H43: 108362.15 | I43: bob.davis@example.com | J43: -8186617944 | K43: Excellent | L43: FALSE
A44: EMP1042 | B44: Alice | C44: Johnson | E44: HR-Nevada | F44: Active | G44: 45629 | H44: 59400.38 | I44: alice.johnson@example.com | J44: -4918017225 | K44: Average | L44: TRUE
...

Sheet Formula_Cleansing
A1: Employee_ID | B1: First_Name | C1: Last_Name | D1: Age | E1: Department_Region | F1: Department | G1: Region | P1: Salary | Q1: Performance_Score | R1: Performance_Bouns
A2: =PROPER(TRIM(CLEAN(RAW_DATA!A2))) -> Emp1000 | B2: =RAW_DATA!B2 -> Bob | C2: =RAW_DATA!C2 -> Davis | D2: =RAW_DATA!D2 -> 25 | E2: =PROPER(TRIM(CLEAN(RAW_DATA!E2))) -> Devops-California | F2: =LEFT(E2, FIND("-", E2) - 1) -> Devops | G2: =RIGHT(E2, LEN(E2) - FIND("-",E2)) -> California | P2: =IF(ISNUMBER(R2), R2, AVERAGEIF($R$2:$R$1000, ">0")) -> 59767.65 | Q2: =IF(PQ_Cleansing!L2="Excellent", P2 * 0.1, IF(PQ_Cleansing!L2="Good", P2 * 0.05, IF(PQ_Cleansing!L2="Average", P2 * 0.02, IF(PQ_Cleansing!L2="Poor", 0, 0)))) -> 1195.353 | R2: =IFERROR(VALUE(SUBSTITUTE(SUBSTITUTE(PQ_Cleansing!I2, "$", ""), ",", "")), "") -> 59767.65
A3: =PROPER(TRIM(CLEAN(RAW_DATA!A3))) -> Emp1001 | B3: =RAW_DATA!B3 -> Bob | C3: =RAW_DATA!C3 -> Brown | D3: =RAW_DATA!D3 -> 0 | E3: =RAW_DATA!E3 -> Finance-Texas | F3: =LEFT(E3, FIND("-", E3) - 1) -> Finance | G3: =RIGHT(E3, LEN(E3) - FIND("-",E3)) -> Texas | P3: =IF(ISNUMBER(R3), R3, AVERAGEIF($R$2:$R$1000, ">0")) -> 65304.66 | Q3: =IF(PQ_Cleansing!L3="Excellent", P3 * 0.1, IF(PQ_Cleansing!L3="Good", P3 * 0.05, IF(PQ_Cleansing!L3="Average", P3 * 0.02, IF(PQ_Cleansing!L3="Poor", 0, 0)))) -> 6530.466 | R3: =IFERROR(VALUE(SUBSTITUTE(SUBSTITUTE(PQ_Cleansing!I3, "$", ""), ",", "")), "") -> 65304.66
A4: =PROPER(TRIM(CLEAN(RAW_DATA!A4))) -> Emp1002 | B4: =RAW_DATA!B4 -> Alice | C4: =RAW_DATA!C4 -> Jones | D4: =RAW_DATA!D4 -> 0 | E4: =RAW_DATA!E4 -> Admin-Nevada | F4: =LEFT(E4, FIND("-", E4) - 1) -> Admin | G4: =RIGHT(E4, LEN(E4) - FIND("-",E4)) -> Nevada | P4: =IF(ISNUMBER(R4), R4, AVERAGEIF($R$2:$R$1000, ">0")) -> 88145.9 | Q4: =IF(PQ_Cleansing!L4="Excellent", P4 * 0.1, IF(PQ_Cleansing!L4="Good", P4 * 0.05, IF(PQ_Cleansing!L4="Average", P4 * 0.02, IF(PQ_Cleansing!L4="Poor", 0, 0)))) -> 4407.295 | R4: =IFERROR(VALUE(SUBSTITUTE(SUBSTITUTE(PQ_Cleansing!I4, "$", ""), ",", "")), "") -> 88145.9
A5: =PROPER(TRIM(CLEAN(RAW_DATA!A5))) -> Emp1003 | B5: =RAW_DATA!B5 -> Eva | C5: =RAW_DATA!C5 -> Davis | D5: =RAW_DATA!D5 -> 25 | E5: =RAW_DATA!E5 -> Admin-Nevada | F5: =LEFT(E5, FIND("-", E5) - 1) -> Admin | G5: =RIGHT(E5, LEN(E5) - FIND("-",E5)) -> Nevada | P5: =IF(ISNUMBER(R5), R5, AVERAGEIF($R$2:$R$1000, ">0")) -> 69450.99 | Q5: =IF(PQ_Cleansing!L5="Excellent", P5 * 0.1, IF(PQ_Cleansing!L5="Good", P5 * 0.05, IF(PQ_Cleansing!L5="Average", P5 * 0.02, IF(PQ_Cleansing!L5="Poor", 0, 0)))) -> 3472.5495 | R5: =IFERROR(VALUE(SUBSTITUTE(SUBSTITUTE(PQ_Cleansing!I5, "$", ""), ",", "")), "") -> 69450.99
A6: =PROPER(TRIM(CLEAN(RAW_DATA!A6))) -> Emp1004 | B6: =RAW_DATA!B6 -> Frank | C6: =RAW_DATA!C6 -> Williams | D6: =RAW_DATA!D6 -> 25 | E6: =RAW_DATA!E6 -> Cloud Tech-Florida | F6: =LEFT(E6, FIND("-", E6) - 1) -> Cloud Tech | G6: =RIGHT(E6, LEN(E6) - FIND("-",E6)) -> Florida | P6: =IF(ISNUMBER(R6), R6, AVERAGEIF($R$2:$R$1000, ">0")) -> 109324.61 | Q6: =IF(PQ_Cleansing!L6="Excellent", P6 * 0.1, IF(PQ_Cleansing!L6="Good", P6 * 0.05, IF(PQ_Cleansing!L6="Average", P6 * 0.02, IF(PQ_Cleansing!L6="Poor", 0, 0)))) -> 0 | R6: =IFERROR(VALUE(SUBSTITUTE(SUBSTITUTE(PQ_Cleansing!I6, "$", ""), ",", "")), "") -> 109324.61
A7: =PROPER(TRIM(CLEAN(RAW_DATA!A7))) -> Emp1005 | B7: =RAW_DATA!B7 -> Alice | C7: =RAW_DATA!C7 -> Garcia | D7: =RAW_DATA!D7 -> 40 | E7: =RAW_DATA!E7 -> Sales-Texas | F7: =LEFT(E7, FIND("-", E7) - 1) -> Sales | G7: =RIGHT(E7, LEN(E7) - FIND("-",E7)) -> Texas | P7: =IF(ISNUMBER(R7), R7, AVERAGEIF($R$2:$R$1000, ">0")) -> 88642.84 | Q7: =IF(PQ_Cleansing!L7="Excellent", P7 * 0.1, IF(PQ_Cleansing!L7="Good", P7 * 0.05, IF(PQ_Cleansing!L7="Average", P7 * 0.02, IF(PQ_Cleansing!L7="Poor", 0, 0)))) -> 4432.142 | R7: =IFERROR(VALUE(SUBSTITUTE(SUBSTITUTE(PQ_Cleansing!I7, "$", ""), ",", "")), "") -> 88642.84
A8: =PROPER(TRIM(CLEAN(RAW_DATA!A8))) -> Emp1006 | B8: =RAW_DATA!B8 -> Frank | C8: =RAW_DATA!C8 -> Jones | D8: =RAW_DATA!D8 -> 0 | E8: =RAW_DATA!E8 -> Admin-Nevada | F8: =LEFT(E8, FIND("-", E8) - 1) -> Admin | G8: =RIGHT(E8, LEN(E8) - FIND("-",E8)) -> Nevada | P8: =IF(ISNUMBER(R8), R8, AVERAGEIF($R$2:$R$1000, ">0")) -> 96288.43 | Q8: =IF(PQ_Cleansing!L8="Excellent", P8 * 0.1, IF(PQ_Cleansing!L8="Good", P8 * 0.05, IF(PQ_Cleansing!L8="Average", P8 * 0.02, IF(PQ_Cleansing!L8="Poor", 0, 0)))) -> 4814.4215 | R8: =IFERROR(VALUE(SUBSTITUTE(SUBSTITUTE(PQ_Cleansing!I8, "$", ""), ",", "")), "") -> 96288.43
A9: =PROPER(TRIM(CLEAN(RAW_DATA!A9))) -> Emp1007 | B9: =RAW_DATA!B9 -> Bob | C9: =RAW_DATA!C9 -> Jones | D9: =RAW_DATA!D9 -> 30 | E9: =RAW_DATA!E9 -> Cloud Tech-Florida | F9: =LEFT(E9, FIND("-", E9) - 1) -> Cloud Tech | G9: =RIGHT(E9, LEN(E9) - FIND("-",E9)) -> Florida | P9: =IF(ISNUMBER(R9), R9, AVERAGEIF($R$2:$R$1000, ">0")) -> 94497.91 | Q9: =IF(PQ_Cleansing!L9="Excellent", P9 * 0.1, IF(PQ_Cleansing!L9="Good", P9 * 0.05, IF(PQ_Cleansing!L9="Average", P9 * 0.02, IF(PQ_Cleansing!L9="Poor", 0, 0)))) -> 1889.9582 | R9: =IFERROR(VALUE(SUBSTITUTE(SUBSTITUTE(PQ_Cleansing!I9, "$", ""), ",", "")), "") -> 94497.91
A10: =PROPER(TRIM(CLEAN(RAW_DATA!A10))) -> Emp1008 | B10: =RAW_DATA!B10 -> Frank | C10: =RAW_DATA!C10 -> Davis | D10: =RAW_DATA!D10 -> 35 | E10: =RAW_DATA!E10 -> Admin-Nevada | F10: =LEFT(E10, FIND("-", E10) - 1) -> Admin | G10: =RIGHT(E10, LEN(E10) - FIND("-",E10)) -> Nevada | P10: =IF(ISNUMBER(R10), R10, AVERAGEIF($R$2:$R$1000, ">0")) -> 115565.82 | Q10: =IF(PQ_Cleansing!L10="Excellent", P10 * 0.1, IF(PQ_Cleansing!L10="Good", P10 * 0.05, IF(PQ_Cleansing!L10="Average", P10 * 0.02, IF(PQ_Cleansing!L10="Poor", 0, 0)))) -> 11556.582 | R10: =IFERROR(VALUE(SUBSTITUTE(SUBSTITUTE(PQ_Cleansing!I10, "$", ""), ",", "")), "") -> 115565.82
A11: =PROPER(TRIM(CLEAN(RAW_DATA!A11))) -> Emp1009 | B11: =RAW_DATA!B11 -> Charlie | C11: =RAW_DATA!C11 -> Johnson | D11: =RAW_DATA!D11 -> 0 | E11: =RAW_DATA!E11 -> DevOps-New York | F11: =LEFT(E11, FIND("-", E11) - 1) -> DevOps | G11: =RIGHT(E11, LEN(E11) - FIND("-",E11)) -> New York | P11: =IF(ISNUMBER(R11), R11, AVERAGEIF($R$2:$R$1000, ">0")) -> 76561.88 | Q11: =IF(PQ_Cleansing!L11="Excellent", P11 * 0.1, IF(PQ_Cleansing!L11="Good", P11 * 0.05, IF(PQ_Cleansing!L11="Average", P11 * 0.02, IF(PQ_Cleansing!L11="Poor", 0, 0)))) -> 7656.188 | R11: =IFERROR(VALUE(SUBSTITUTE(SUBSTITUTE(PQ_Cleansing!I11, "$", ""), ",", "")), "") -> 76561.88
A12: =PROPER(TRIM(CLEAN(RAW_DATA!A12))) -> Emp1010 | B12: =RAW_DATA!B12 -> David | C12: =RAW_DATA!C12 -> Williams | D12: =RAW_DATA!D12 -> 35 | E12: =RAW_DATA!E12 -> Cloud Tech-New York | F12: =LEFT(E12, FIND("-", E12) - 1) -> Cloud Tech | G12: =RIGHT(E12, LEN(E12) - FIND("-",E12)) -> New York | P12: =IF(ISNUMBER(R12), R12, AVERAGEIF($R$2:$R$1000, ">0")) -> 72081.71 | Q12: =IF(PQ_Cleansing!L12="Excellent", P12 * 0.1, IF(PQ_Cleansing!L12="Good", P12 * 0.05, IF(PQ_Cleansing!L12="Average", P12 * 0.02, IF(PQ_Cleansing!L12="Poor", 0, 0)))) -> 1441.6342 | R12: =IFERROR(VALUE(SUBSTITUTE(SUBSTITUTE(PQ_Cleansing!I12, "$", ""), ",", "")), "") -> 72081.71
A13: =PROPER(TRIM(CLEAN(RAW_DATA!A13))) -> Emp1011 | B13: =RAW_DATA!B13 -> David | C13: =RAW_DATA!C13 -> Davis | D13: =RAW_DATA!D13 -> 0 | E13: =RAW_DATA!E13 -> DevOps-California | F13: =LEFT(E13, FIND("-", E13) - 1) -> DevOps | G13: =RIGHT(E13, LEN(E13) - FIND("-",E13)) -> California | P13: =IF(ISNUMBER(R13), R13, AVERAGEIF($R$2:$R$1000, ">0")) -> 84946.19 | Q13: =IF(PQ_Cleansing!L13="Excellent", P13 * 0.1, IF(PQ_Cleansing!L13="Good", P13 * 0.05, IF(PQ_Cleansing!L13="Average", P13 * 0.02, IF(PQ_Cleansing!L13="Poor", 0, 0)))) -> 0 | R13: =IFERROR(VALUE(SUBSTITUTE(SUBSTITUTE(PQ_Cleansing!I13, "$", ""), ",", "")), "") -> 84946.19
A14: =PROPER(TRIM(CLEAN(RAW_DATA!A14))) -> Emp1012 | B14: =RAW_DATA!B14 -> Heidi | C14: =RAW_DATA!C14 -> Williams | D14: =RAW_DATA!D14 -> 30 | E14: =RAW_DATA!E14 -> HR-New York | F14: =LEFT(E14, FIND("-", E14) - 1) -> HR | G14: =RIGHT(E14, LEN(E14) - FIND("-",E14)) -> New York | P14: =IF(ISNUMBER(R14), R14, AVERAGEIF($R$2:$R$1000, ">0")) -> 89295.77 | Q14: =IF(PQ_Cleansing!L14="Excellent", P14 * 0.1, IF(PQ_Cleansing!L14="Good", P14 * 0.05, IF(PQ_Cleansing!L14="Average", P14 * 0.02, IF(PQ_Cleansing!L14="Poor", 0, 0)))) -> 8929.577 | R14: =IFERROR(VALUE(SUBSTITUTE(SUBSTITUTE(PQ_Cleansing!I14, "$", ""), ",", "")), "") -> 89295.77
... A1021: =PROPER(TRIM(CLEAN(RAW_DATA!A1021))) -> Emp2019 | B1021: =RAW_DATA!B1021 -> Heidi | C1021: =RAW_DATA!C1021 -> Jones | D1021: =RAW_DATA!D1021 -> 30 | E1021: =RAW_DATA!E1021 -> DevOps-Illinois | F1021: =LEFT(E1021, FIND("-", E1021) - 1) -> DevOps | G1021: =RIGHT(E1021, LEN(E1021) - FIND("-",E1021)) -> Illinois | P1021: =IF(ISNUMBER(R1021), R1021, AVERAGEIF($R$2:$R$1000, ">0")) -> 77764.24 | Q1021: =IF(PQ_Cleansing!L1021="Excellent", P1021 * 0.1, IF(PQ_Cleansing!L1021="Good", P1021 * 0.05, IF(PQ_Cleansing!L1021="Average", P1021 * 0.02, IF(PQ_Cleansing!L1021="Poor", 0, 0)))) -> 1555.2848 | R1021: =IFERROR(VALUE(SUBSTITUTE(SUBSTITUTE(PQ_Cleansing!I1021, "$", ""), ",", "")), "") -> 77764.24

Sheet PQ_Cleansing
A1: Employee_ID | B1: First_Name | C1: Last_Name | D1: Age | E1: Department_Region.1 | F1: Department_Region.2 | G1: Status | H1: Join_Date | I1: Salary | J1: Email | K1: Phone | L1: Performance_Score | M1: Remote_Work | N1: Performance_Bouns
A2: EMP1000 | B2: Bob | C2: Davis | D2: 25 | E2: Devops | F2: California | G2: Active | H2: 44288 | I2: 59767.65 | J2: bob.davis@example.com | K2: -1651623197 | L2: Average | M2: TRUE | N2: 1195.353
A3: EMP1001 | B3: Bob | C3: Brown | E3: Finance | F3: Texas | G3: Active | H3: 44022 | I3: 65304.66 | J3: bob.brown@example.com | K3: -1898471390 | L3: Excellent | M3: TRUE | N3: 6530.466
A4: EMP1002 | B4: Alice | C4: Jones | E4: Admin | F4: Nevada | G4: Pending | H4: 45267 | I4: 88145.9 | J4: alice.jones@example.com | K4: -5596363211 | L4: Good | M4: TRUE | N4: 4407.295
A5: EMP1003 | B5: Eva | C5: Davis | D5: 25 | E5: Admin | F5: Nevada | G5: Inactive | H5: 44527 | I5: 69450.99 | J5: eva.davis@example.com | K5: -3476490784 | L5: Good | M5: TRUE | N5: 3472.5495
A6: EMP1004 | B6: Frank | C6: Williams | D6: 25 | E6: Cloud Tech | F6: Florida | G6: Active | H6: 44566 | I6: 109324.61 | J6: frank.williams@example.com | K6: -1586734256 | L6: Poor | M6: FALSE | N6: 0
A7: EMP1005 | B7: Alice | C7: Garcia | D7: 40 | E7: Sales | F7: Texas | G7: Inactive | H7: 43992 | I7: 88642.84 | J7: alice.garcia@example.com | K7: -5409003485 | L7: Good | M7: FALSE | N7: 4432.142
A8: EMP1006 | B8: Frank | C8: Jones | E8: Admin | F8: Nevada | G8: Active | H8: 43924 | I8: 96288.43 | J8: frank.jones@example.com | K8: -4518376063 | L8: Good | M8: FALSE | N8: 4814.4215
A9: EMP1007 | B9: Bob | C9: Jones | D9: 30 | E9: Cloud Tech | F9: Florida | G9: Inactive | H9: 44759 | I9: 94497.91 | J9: bob.jones@example.com | K9: -4134327559 | L9: Average | M9: TRUE | N9: 1889.9582
A10: EMP1008 | B10: Frank | C10: Davis | D10: 35 | E10: Admin | F10: Nevada | G10: Inactive | H10: 45268 | I10: 115565.82 | J10: frank.davis@example.com | K10: -4177656123 | L10: Excellent | M10: TRUE | N10: 11556.582
A11: EMP1009 | B11: Charlie | C11: Johnson | E11: Devops | F11: New York | G11: Active | H11: 44777 | I11: 76561.88 | J11: charlie.johnson@example.com | K11: -8156985699 | L11: Excellent | M11: TRUE | N11: 7656.188
A12: EMP1010 | B12: David | C12: Williams | D12: 35 | E12: Cloud Tech | F12: New York | G12: Active | H12: 45479 | I12: 72081.71 | J12: david.williams@example.com | K12: -2720634590 | L12: Average | M12: FALSE | N12: 1441.6342
A13: EMP1011 | B13: David | C13: Davis | E13: Devops | F13: California | G13: Active | H13: 45173 | I13: 84946.19 | J13: david.davis@example.com | K13: -1238296576 | L13: Poor | M13: TRUE | N13: 0
A14: EMP1012 | B14: Heidi | C14: Williams | D14: 30 | E14: Hr | F14: New York | G14: Active | H14: 45356 | I14: 89295.77 | J14: heidi.williams@example.com | K14: -2429543164 | L14: Excellent | M14: FALSE | N14: 8929.577
A15: EMP1013 | B15: Grace | C15: Williams | E15: Finance | F15: California | G15: Active | H15: 44114 | I15: 85666.84 | J15: grace.williams@example.com | K15: -2669300892 | L15: Good | M15: FALSE | N15: 4283.342
A16: EMP1014 | B16: Alice | C16: Garcia | D16: 25 | E16: Admin | F16: Nevada | G16: Active | H16: 45453 | I16: 97633.68 | J16: alice.garcia@example.com | K16: -1734206968 | L16: Excellent | M16: TRUE | N16: 9763.368
A17: EMP1015 | B17: Grace | C17: Jones | D17: 40 | E17: Sales | F17: Florida | G17: Pending | H17: 44345 | I17: 117975.49 | J17: grace.jones@example.com | K17: -4215291085 | L17: Good | M17: TRUE | N17: 5898.7745
A18: EMP1016 | B18: Alice | C18: Brown | D18: 25 | E18: Devops | F18: Illinois | G18: Inactive | H18: 45405 | I18: 94867.33 | J18: alice.brown@example.com | K18: -7713334475 | L18: Poor | M18: FALSE | N18: 0
A19: EMP1017 | B19: Grace | C19: Garcia | D19: 30 | E19: Finance | F19: Texas | G19: Pending | H19: 45624 | I19: 100377.65 | J19: grace.garcia@example.com | K19: -2639343625 | L19: Average | M19: TRUE | N19: 2007.553
A20: EMP1018 | B20: Charlie | C20: Garcia | E20: Cloud Tech | F20: Nevada | G20: Inactive | H20: 45554 | I20: 94726.46 | J20: charlie.garcia@example.com | K20: -2044397358 | L20: Excellent | M20: FALSE | N20: 9472.646
A21: EMP1019 | B21: Charlie | C21: Williams | D21: 35 | E21: Admin | F21: Illinois | G21: Pending | H21: 43832 | I21: 91926.12 | J21: charlie.williams@example.com | K21: -7107256365 | L21: Average | M21: TRUE | N21: 1838.5224
A22: EMP1020 | B22: Bob | C22: Miller | D22: 35 | E22: Hr | F22: New York | G22: Active | H22: 44324 | I22: 111460.67 | J22: bob.miller@example.com | K22: -9411800536 | L22: Excellent | M22: TRUE | N22: 11146.067
A23: EMP1021 | B23: Bob | C23: Jones | D23: 40 | E23: Cloud Tech | F23: Illinois | G23: Active | H23: 44093 | I23: 96182.56 | J23: bob.jones@example.com | K23: -5990048963 | L23: Good | M23: FALSE | N23: 4809.128
A24: EMP1022 | B24: Charlie | C24: Johnson | D24: 35 | E24: Sales | F24: Illinois | G24: Inactive | H24: 44264 | I24: 115023.94 | J24: charlie.johnson@example.com | K24: -6528092427 | L24: Average | M24: TRUE | N24: 2300.4788
A25: EMP1023 | B25: David | C25: Garcia | D25: 35 | E25: Finance | F25: Nevada | G25: Pending | H25: 44595 | I25: 80667.01 | J25: david.garcia@example.com | K25: -7572158623 | L25: Excellent | M25: FALSE | N25: 8066.701
A26: EMP1024 | B26: Bob | C26: Brown | D26: 30 | E26: Admin | F26: Texas | G26: Inactive | H26: 43874 | I26: 91181.61 | J26: bob.brown@example.com | K26: -1502745643 | L26: Good | M26: TRUE | N26: 4559.0805
A27: EMP1025 | B27: David | C27: Miller | D27: 25 | E27: Cloud Tech | F27: Nevada | G27: Pending | H27: 43951 | I27: 66025.92 | J27: david.miller@example.com | K27: -9485625727 | L27: Average | M27: FALSE | N27: 1320.5184
A28: EMP1026 | B28: Frank | C28: Miller | D28: 25 | E28: Sales | F28: New York | G28: Inactive | H28: 45201 | I28: 83979.01 | J28: frank.miller@example.com | K28: -7032032073 | L28: Average | M28: FALSE | N28: 1679.5802
A29: EMP1027 | B29: Heidi | C29: Johnson | D29: 30 | E29: Finance | F29: Florida | G29: Active | H29: 44024 | I29: 56785.16 | J29: heidi.johnson@example.com | K29: -2761707586 | L29: Excellent | M29: TRUE | N29: 5678.516
A30: EMP1028 | B30: Grace | C30: Garcia | D30: 40 | E30: Finance | F30: Nevada | G30: Active | H30: 45210 | I30: 95741.88 | J30: grace.garcia@example.com | K30: -7712151341 | L30: Excellent | M30: FALSE | N30: 9574.188
A31: EMP1029 | B31: Alice | C31: Brown | D31: 40 | E31: Devops | F31: California | G31: Active | H31: 44340 | I31: 63411.31 | J31: alice.brown@example.com | K31: -2849939088 | L31: Excellent | M31: TRUE | N31: 6341.131
A32: EMP1030 | B32: Charlie | C32: Jones | D32: 40 | E32: Admin | F32: California | G32: Inactive | H32: 44342 | I32: 111214.02 | J32: charlie.jones@example.com | K32: -2613715040 | L32: Good | M32: TRUE | N32: 5560.701
... A37: EMP1035 | B37: Frank | C37: Jones | D37: 25 | E37: Cloud Tech | F37: Illinois | G37: Inactive | H37: 44860 | I37: 114357.1 | J37: frank.jones@example.com | K37: -6642147648 | L37: Excellent | M37: TRUE | N37: 11435.71
A38: EMP1036 | B38: Alice | C38: Brown | E38: Cloud Tech | F38: New York | G38: Active | H38: 45049 | I38: 54757.26 | J38: alice.brown@example.com | K38: -2515837766 | L38: Poor | M38: FALSE | N38: 0
A39: EMP1037 | B39: Grace | C39: Smith | D39: 25 | E39: Sales | F39: New York | G39: Pending | H39: 45048 | I39: 52781.92 | J39: grace.smith@example.com | K39: -4996165925 | L39: Average | M39: TRUE | N39: 1055.6384
A40: EMP1038 | B40: Frank | C40: Smith | D40: 35 | E40: Admin | F40: Nevada | G40: Pending | H40: 44474 | I40: 66708.02 | J40: frank.smith@example.com | K40: -6108573277 | L40: Good | M40: TRUE | N40: 3335.401
A41: EMP1039 | B41: Eva | C41: Williams | D41: 40 | E41: Hr | F41: Texas | G41: Active | H41: 44769 | I41: 93481.15 | J41: eva.williams@example.com | K41: -8147617421 | L41: Poor | M41: FALSE | N41: 0
A42: EMP1040 | B42: Bob | C42: Williams | D42: 25 | E42: Sales | F42: New York | G42: Pending | H42: 44374 | I42: 59271.96 | J42: bob.williams@example.com | K42: -4386490809 | L42: Excellent | M42: TRUE | N42: 5927.196
A43: EMP1041 | B43: Bob | C43: Davis | D43: 30 | E43: Hr | F43: California | G43: Active | H43: 44728 | I43: 108362.15 | J43: bob.davis@example.com | K43: -8186617944 | L43: Excellent | M43: FALSE | N43: 10836.215
A44: EMP1042 | B44: Alice | C44: Johnson | E44: Hr | F44: Nevada | G44: Active | H44: 45629 | I44: 59400.38 | J44: alice.johnson@example.com | K44: -4918017225 | L44: Average | M44: TRUE | N44: 1188.0076
...
